1.
```
fun main() = runBlocking {
    val job = CoroutineScope(EmptyCoroutineContext).launch {
        launch {
            delay(500)
            println("ok") // <--
        }
        launch {
            delay(500)
            println("ok")
        }
    }
    delay(100)
    job.cancelAndJoin()
}
```

Не отработает, так как main завершится ранее, чем корутины с задержкой 500

2.
```
fun main() = runBlocking {
    val job = CoroutineScope(EmptyCoroutineContext).launch {
        val child = launch {
            delay(500)
            println("ok") // <--
        }
        launch {
            delay(500)
            println("ok")
        }
        delay(100)
        child.cancel()
    }
    delay(100)
    job.join()
}
```

Не отработает, так как корутина отменится раньше, чем напечатется строка.

3.
```
fun main() {
    with(CoroutineScope(EmptyCoroutineContext)) {
        try {
            launch {
                throw Exception("something bad happened")
            }
        } catch (e: Exception) {
            e.printStackTrace() // <--
        }
    }
    Thread.sleep(1000)
}
```

Не  выполнится, try не перехватит исключения.

4.
```
fun main() {
    CoroutineScope(EmptyCoroutineContext).launch {
        try {
            coroutineScope {
                throw Exception("something bad happened")
            }
        } catch (e: Exception) {
            e.printStackTrace() // <--
        }
    }
    Thread.sleep(1000)
}
```

Выполнится, coroutineScope перехватит ошибку.

5.
```
fun main() {
    CoroutineScope(EmptyCoroutineContext).launch {
        try {
            supervisorScope {
                throw Exception("something bad happened")
            }
        } catch (e: Exception) {
            e.printStackTrace() // <--
        }
    }
    Thread.sleep(1000)
}
```

Выполнится, так как внутри supervisorScope нет корутин.

6.
```
fun main() {
    CoroutineScope(EmptyCoroutineContext).launch {
        try {
            coroutineScope {
                launch {
                    delay(500)
                    throw Exception("something bad happened") // <--
                }
                launch {
                    throw Exception("something bad happened")
                }
            }
        } catch (e: Exception) {
            e.printStackTrace()
        }
    }
    Thread.sleep(1000)
}
```

Не выполнится, так как второй launch выполнится раньше, сработает Exception и coroutineScope прервет все вложенные корутины.

7.
```
fun main() {
    CoroutineScope(EmptyCoroutineContext).launch {
        try {
            supervisorScope {
                launch {
                    delay(500)
                    throw Exception("something bad happened") // <--
                }
                launch {
                    throw Exception("something bad happened")
                }
            }
        } catch (e: Exception) {
            e.printStackTrace() // <--
        }
    }
    Thread.sleep(1000)
}
```

Выполнится, так как supervisorScope не прерывает вложенные корутины, если в одной из них случается исключение.

8.
```
fun main() {
    CoroutineScope(EmptyCoroutineContext).launch {
        CoroutineScope(EmptyCoroutineContext).launch {
            launch {
                delay(1000)
                println("ok") // <--
            }
            launch {
                delay(500)
                println("ok")
            }
            throw Exception("something bad happened")
        }
    }
    Thread.sleep(1000)
}
```

Не выполнится, так как исключение остановит родительскую корутину, а родительская остановит дочерние.

9.
```
fun main() {
    CoroutineScope(EmptyCoroutineContext).launch {
        CoroutineScope(EmptyCoroutineContext + SupervisorJob()).launch {
            launch {
                delay(1000)
                println("ok") // <--
            }
            launch {
                delay(500)
                println("ok")
            }
            throw Exception("something bad happened")
        }
    }
    Thread.sleep(1000)
}
```

Не выполнится, так как SupervisorJob не останавливает остальные дочерние в случае ошибки в одной из них, но тут
дочерняя только одна launch и исключение возникает в ней, соответственно две корутины не выполнятся.